{
 "cells": [
  {
   "cell_type": "code",
   "execution_count": 1,
   "metadata": {},
   "outputs": [
    {
     "name": "stdout",
     "output_type": "stream",
     "text": [
      "Populating the interactive namespace from numpy and matplotlib\n"
     ]
    }
   ],
   "source": [
    "%pylab inline\n",
    "%load_ext autoreload\n",
    "%autoreload 2"
   ]
  },
  {
   "cell_type": "code",
   "execution_count": 3,
   "metadata": {},
   "outputs": [
    {
     "name": "stderr",
     "output_type": "stream",
     "text": [
      "ERROR:root:Internal Python error in the inspect module.\n",
      "Below is the traceback from this internal error.\n",
      "\n",
      "ERROR:root:Internal Python error in the inspect module.\n",
      "Below is the traceback from this internal error.\n",
      "\n"
     ]
    },
    {
     "name": "stdout",
     "output_type": "stream",
     "text": [
      "Traceback (most recent call last):\n",
      "  File \"/home/haehn/miniconda3/envs/CLASSIFIER/lib/python3.6/pkgutil.py\", line 412, in get_importer\n",
      "    importer = sys.path_importer_cache[path_item]\n",
      "KeyError: ''\n",
      "\n",
      "During handling of the above exception, another exception occurred:\n",
      "\n",
      "Traceback (most recent call last):\n",
      "  File \"/home/haehn/miniconda3/envs/CLASSIFIER/lib/python3.6/site-packages/IPython/core/interactiveshell.py\", line 3319, in run_code\n",
      "    exec(code_obj, self.user_global_ns, self.user_ns)\n",
      "  File \"<ipython-input-3-646b77a14b27>\", line 14, in <module>\n",
      "    from detectron2 import model_zoo\n",
      "  File \"/home/haehn/Projects/classifiers/externals/detectron2/detectron2/model_zoo/__init__.py\", line 7, in <module>\n",
      "    from .model_zoo import get, get_config_file, get_checkpoint_url\n",
      "  File \"/home/haehn/Projects/classifiers/externals/detectron2/detectron2/model_zoo/model_zoo.py\", line 3, in <module>\n",
      "    import pkg_resources\n",
      "  File \"/home/haehn/miniconda3/envs/CLASSIFIER/lib/python3.6/site-packages/pkg_resources/__init__.py\", line 3251, in <module>\n",
      "    @_call_aside\n",
      "  File \"/home/haehn/miniconda3/envs/CLASSIFIER/lib/python3.6/site-packages/pkg_resources/__init__.py\", line 3235, in _call_aside\n",
      "    f(*args, **kwargs)\n",
      "  File \"/home/haehn/miniconda3/envs/CLASSIFIER/lib/python3.6/site-packages/pkg_resources/__init__.py\", line 3264, in _initialize_master_working_set\n",
      "    working_set = WorkingSet._build_master()\n",
      "  File \"/home/haehn/miniconda3/envs/CLASSIFIER/lib/python3.6/site-packages/pkg_resources/__init__.py\", line 574, in _build_master\n",
      "    ws = cls()\n",
      "  File \"/home/haehn/miniconda3/envs/CLASSIFIER/lib/python3.6/site-packages/pkg_resources/__init__.py\", line 567, in __init__\n",
      "    self.add_entry(entry)\n",
      "  File \"/home/haehn/miniconda3/envs/CLASSIFIER/lib/python3.6/site-packages/pkg_resources/__init__.py\", line 623, in add_entry\n",
      "    for dist in find_distributions(entry, True):\n",
      "  File \"/home/haehn/miniconda3/envs/CLASSIFIER/lib/python3.6/site-packages/pkg_resources/__init__.py\", line 1969, in find_distributions\n",
      "    importer = get_importer(path_item)\n",
      "  File \"/home/haehn/miniconda3/envs/CLASSIFIER/lib/python3.6/pkgutil.py\", line 416, in get_importer\n",
      "    importer = path_hook(path_item)\n",
      "  File \"<frozen importlib._bootstrap_external>\", line 1324, in path_hook_for_FileFinder\n",
      "  File \"<frozen importlib._bootstrap_external>\", line 102, in _path_isdir\n",
      "FileNotFoundError: [Errno 2] No such file or directory\n",
      "\n",
      "During handling of the above exception, another exception occurred:\n",
      "\n",
      "Traceback (most recent call last):\n",
      "  File \"/home/haehn/miniconda3/envs/CLASSIFIER/lib/python3.6/site-packages/IPython/core/interactiveshell.py\", line 2034, in showtraceback\n",
      "    stb = value._render_traceback_()\n",
      "AttributeError: 'FileNotFoundError' object has no attribute '_render_traceback_'\n",
      "\n",
      "During handling of the above exception, another exception occurred:\n",
      "\n",
      "Traceback (most recent call last):\n",
      "  File \"/home/haehn/miniconda3/envs/CLASSIFIER/lib/python3.6/site-packages/IPython/core/ultratb.py\", line 1151, in get_records\n",
      "    return _fixed_getinnerframes(etb, number_of_lines_of_context, tb_offset)\n",
      "  File \"/home/haehn/miniconda3/envs/CLASSIFIER/lib/python3.6/site-packages/IPython/core/ultratb.py\", line 319, in wrapped\n",
      "    return f(*args, **kwargs)\n",
      "  File \"/home/haehn/miniconda3/envs/CLASSIFIER/lib/python3.6/site-packages/IPython/core/ultratb.py\", line 353, in _fixed_getinnerframes\n",
      "    records = fix_frame_records_filenames(inspect.getinnerframes(etb, context))\n",
      "  File \"/home/haehn/miniconda3/envs/CLASSIFIER/lib/python3.6/inspect.py\", line 1490, in getinnerframes\n",
      "    frameinfo = (tb.tb_frame,) + getframeinfo(tb, context)\n",
      "  File \"/home/haehn/miniconda3/envs/CLASSIFIER/lib/python3.6/inspect.py\", line 1448, in getframeinfo\n",
      "    filename = getsourcefile(frame) or getfile(frame)\n",
      "  File \"/home/haehn/miniconda3/envs/CLASSIFIER/lib/python3.6/inspect.py\", line 696, in getsourcefile\n",
      "    if getattr(getmodule(object, filename), '__loader__', None) is not None:\n",
      "  File \"/home/haehn/miniconda3/envs/CLASSIFIER/lib/python3.6/inspect.py\", line 725, in getmodule\n",
      "    file = getabsfile(object, _filename)\n",
      "  File \"/home/haehn/miniconda3/envs/CLASSIFIER/lib/python3.6/inspect.py\", line 709, in getabsfile\n",
      "    return os.path.normcase(os.path.abspath(_filename))\n",
      "  File \"/home/haehn/miniconda3/envs/CLASSIFIER/lib/python3.6/posixpath.py\", line 383, in abspath\n",
      "    cwd = os.getcwd()\n",
      "FileNotFoundError: [Errno 2] No such file or directory\n",
      "Traceback (most recent call last):\n",
      "  File \"/home/haehn/miniconda3/envs/CLASSIFIER/lib/python3.6/pkgutil.py\", line 412, in get_importer\n",
      "    importer = sys.path_importer_cache[path_item]\n",
      "KeyError: ''\n",
      "\n",
      "During handling of the above exception, another exception occurred:\n",
      "\n",
      "Traceback (most recent call last):\n",
      "  File \"/home/haehn/miniconda3/envs/CLASSIFIER/lib/python3.6/site-packages/IPython/core/interactiveshell.py\", line 3319, in run_code\n",
      "    exec(code_obj, self.user_global_ns, self.user_ns)\n",
      "  File \"<ipython-input-3-646b77a14b27>\", line 14, in <module>\n",
      "    from detectron2 import model_zoo\n",
      "  File \"/home/haehn/Projects/classifiers/externals/detectron2/detectron2/model_zoo/__init__.py\", line 7, in <module>\n",
      "    from .model_zoo import get, get_config_file, get_checkpoint_url\n",
      "  File \"/home/haehn/Projects/classifiers/externals/detectron2/detectron2/model_zoo/model_zoo.py\", line 3, in <module>\n",
      "    import pkg_resources\n",
      "  File \"/home/haehn/miniconda3/envs/CLASSIFIER/lib/python3.6/site-packages/pkg_resources/__init__.py\", line 3251, in <module>\n",
      "    @_call_aside\n",
      "  File \"/home/haehn/miniconda3/envs/CLASSIFIER/lib/python3.6/site-packages/pkg_resources/__init__.py\", line 3235, in _call_aside\n",
      "    f(*args, **kwargs)\n",
      "  File \"/home/haehn/miniconda3/envs/CLASSIFIER/lib/python3.6/site-packages/pkg_resources/__init__.py\", line 3264, in _initialize_master_working_set\n",
      "    working_set = WorkingSet._build_master()\n",
      "  File \"/home/haehn/miniconda3/envs/CLASSIFIER/lib/python3.6/site-packages/pkg_resources/__init__.py\", line 574, in _build_master\n",
      "    ws = cls()\n",
      "  File \"/home/haehn/miniconda3/envs/CLASSIFIER/lib/python3.6/site-packages/pkg_resources/__init__.py\", line 567, in __init__\n",
      "    self.add_entry(entry)\n",
      "  File \"/home/haehn/miniconda3/envs/CLASSIFIER/lib/python3.6/site-packages/pkg_resources/__init__.py\", line 623, in add_entry\n",
      "    for dist in find_distributions(entry, True):\n",
      "  File \"/home/haehn/miniconda3/envs/CLASSIFIER/lib/python3.6/site-packages/pkg_resources/__init__.py\", line 1969, in find_distributions\n",
      "    importer = get_importer(path_item)\n",
      "  File \"/home/haehn/miniconda3/envs/CLASSIFIER/lib/python3.6/pkgutil.py\", line 416, in get_importer\n",
      "    importer = path_hook(path_item)\n",
      "  File \"<frozen importlib._bootstrap_external>\", line 1324, in path_hook_for_FileFinder\n",
      "  File \"<frozen importlib._bootstrap_external>\", line 102, in _path_isdir\n",
      "FileNotFoundError: [Errno 2] No such file or directory\n",
      "\n",
      "During handling of the above exception, another exception occurred:\n",
      "\n",
      "Traceback (most recent call last):\n",
      "  File \"/home/haehn/miniconda3/envs/CLASSIFIER/lib/python3.6/site-packages/IPython/core/interactiveshell.py\", line 2034, in showtraceback\n",
      "    stb = value._render_traceback_()\n",
      "AttributeError: 'FileNotFoundError' object has no attribute '_render_traceback_'\n",
      "\n",
      "During handling of the above exception, another exception occurred:\n",
      "\n",
      "Traceback (most recent call last):\n",
      "  File \"/home/haehn/miniconda3/envs/CLASSIFIER/lib/python3.6/site-packages/IPython/core/interactiveshell.py\", line 3242, in run_ast_nodes\n",
      "    if (await self.run_code(code, result,  async_=asy)):\n",
      "  File \"/home/haehn/miniconda3/envs/CLASSIFIER/lib/python3.6/site-packages/IPython/core/interactiveshell.py\", line 3336, in run_code\n",
      "    self.showtraceback(running_compiled_code=True)\n",
      "  File \"/home/haehn/miniconda3/envs/CLASSIFIER/lib/python3.6/site-packages/IPython/core/interactiveshell.py\", line 2037, in showtraceback\n",
      "    value, tb, tb_offset=tb_offset)\n",
      "  File \"/home/haehn/miniconda3/envs/CLASSIFIER/lib/python3.6/site-packages/IPython/core/ultratb.py\", line 1418, in structured_traceback\n",
      "    self, etype, value, tb, tb_offset, number_of_lines_of_context)\n",
      "  File \"/home/haehn/miniconda3/envs/CLASSIFIER/lib/python3.6/site-packages/IPython/core/ultratb.py\", line 1318, in structured_traceback\n",
      "    self, etype, value, tb, tb_offset, number_of_lines_of_context\n",
      "  File \"/home/haehn/miniconda3/envs/CLASSIFIER/lib/python3.6/site-packages/IPython/core/ultratb.py\", line 1186, in structured_traceback\n",
      "    formatted_exceptions += self.prepare_chained_exception_message(evalue.__cause__)\n",
      "TypeError: must be str, not list\n",
      "\n",
      "During handling of the above exception, another exception occurred:\n",
      "\n",
      "Traceback (most recent call last):\n",
      "  File \"/home/haehn/miniconda3/envs/CLASSIFIER/lib/python3.6/site-packages/IPython/core/interactiveshell.py\", line 2034, in showtraceback\n",
      "    stb = value._render_traceback_()\n",
      "AttributeError: 'TypeError' object has no attribute '_render_traceback_'\n",
      "\n",
      "During handling of the above exception, another exception occurred:\n",
      "\n",
      "Traceback (most recent call last):\n",
      "  File \"/home/haehn/miniconda3/envs/CLASSIFIER/lib/python3.6/site-packages/IPython/core/ultratb.py\", line 1151, in get_records\n",
      "    return _fixed_getinnerframes(etb, number_of_lines_of_context, tb_offset)\n",
      "  File \"/home/haehn/miniconda3/envs/CLASSIFIER/lib/python3.6/site-packages/IPython/core/ultratb.py\", line 319, in wrapped\n",
      "    return f(*args, **kwargs)\n",
      "  File \"/home/haehn/miniconda3/envs/CLASSIFIER/lib/python3.6/site-packages/IPython/core/ultratb.py\", line 353, in _fixed_getinnerframes\n",
      "    records = fix_frame_records_filenames(inspect.getinnerframes(etb, context))\n",
      "  File \"/home/haehn/miniconda3/envs/CLASSIFIER/lib/python3.6/inspect.py\", line 1490, in getinnerframes\n",
      "    frameinfo = (tb.tb_frame,) + getframeinfo(tb, context)\n",
      "  File \"/home/haehn/miniconda3/envs/CLASSIFIER/lib/python3.6/inspect.py\", line 1448, in getframeinfo\n",
      "    filename = getsourcefile(frame) or getfile(frame)\n",
      "  File \"/home/haehn/miniconda3/envs/CLASSIFIER/lib/python3.6/inspect.py\", line 696, in getsourcefile\n",
      "    if getattr(getmodule(object, filename), '__loader__', None) is not None:\n",
      "  File \"/home/haehn/miniconda3/envs/CLASSIFIER/lib/python3.6/inspect.py\", line 725, in getmodule\n",
      "    file = getabsfile(object, _filename)\n",
      "  File \"/home/haehn/miniconda3/envs/CLASSIFIER/lib/python3.6/inspect.py\", line 709, in getabsfile\n",
      "    return os.path.normcase(os.path.abspath(_filename))\n",
      "  File \"/home/haehn/miniconda3/envs/CLASSIFIER/lib/python3.6/posixpath.py\", line 383, in abspath\n",
      "    cwd = os.getcwd()\n",
      "FileNotFoundError: [Errno 2] No such file or directory\n"
     ]
    },
    {
     "ename": "TypeError",
     "evalue": "must be str, not list",
     "output_type": "error",
     "traceback": [
      "\u001b[0;31m---------------------------------------------------------------------------\u001b[0m",
      "\u001b[0;31mKeyError\u001b[0m                                  Traceback (most recent call last)",
      "\u001b[0;32m~/miniconda3/envs/CLASSIFIER/lib/python3.6/pkgutil.py\u001b[0m in \u001b[0;36mget_importer\u001b[0;34m(path_item)\u001b[0m\n\u001b[1;32m    411\u001b[0m     \u001b[0;32mtry\u001b[0m\u001b[0;34m:\u001b[0m\u001b[0;34m\u001b[0m\u001b[0;34m\u001b[0m\u001b[0m\n\u001b[0;32m--> 412\u001b[0;31m         \u001b[0mimporter\u001b[0m \u001b[0;34m=\u001b[0m \u001b[0msys\u001b[0m\u001b[0;34m.\u001b[0m\u001b[0mpath_importer_cache\u001b[0m\u001b[0;34m[\u001b[0m\u001b[0mpath_item\u001b[0m\u001b[0;34m]\u001b[0m\u001b[0;34m\u001b[0m\u001b[0;34m\u001b[0m\u001b[0m\n\u001b[0m\u001b[1;32m    413\u001b[0m     \u001b[0;32mexcept\u001b[0m \u001b[0mKeyError\u001b[0m\u001b[0;34m:\u001b[0m\u001b[0;34m\u001b[0m\u001b[0;34m\u001b[0m\u001b[0m\n",
      "\u001b[0;31mKeyError\u001b[0m: ''",
      "\nDuring handling of the above exception, another exception occurred:\n",
      "\nDuring handling of the above exception, another exception occurred:\n",
      "\u001b[0;31mAttributeError\u001b[0m                            Traceback (most recent call last)",
      "\u001b[0;32m~/miniconda3/envs/CLASSIFIER/lib/python3.6/site-packages/IPython/core/interactiveshell.py\u001b[0m in \u001b[0;36mshowtraceback\u001b[0;34m(self, exc_tuple, filename, tb_offset, exception_only, running_compiled_code)\u001b[0m\n\u001b[1;32m   2033\u001b[0m                         \u001b[0;31m# in the engines. This should return a list of strings.\u001b[0m\u001b[0;34m\u001b[0m\u001b[0;34m\u001b[0m\u001b[0;34m\u001b[0m\u001b[0m\n\u001b[0;32m-> 2034\u001b[0;31m                         \u001b[0mstb\u001b[0m \u001b[0;34m=\u001b[0m \u001b[0mvalue\u001b[0m\u001b[0;34m.\u001b[0m\u001b[0m_render_traceback_\u001b[0m\u001b[0;34m(\u001b[0m\u001b[0;34m)\u001b[0m\u001b[0;34m\u001b[0m\u001b[0;34m\u001b[0m\u001b[0m\n\u001b[0m\u001b[1;32m   2035\u001b[0m                     \u001b[0;32mexcept\u001b[0m \u001b[0mException\u001b[0m\u001b[0;34m:\u001b[0m\u001b[0;34m\u001b[0m\u001b[0;34m\u001b[0m\u001b[0m\n",
      "\u001b[0;31mAttributeError\u001b[0m: 'FileNotFoundError' object has no attribute '_render_traceback_'",
      "\nDuring handling of the above exception, another exception occurred:\n",
      "\u001b[0;31mTypeError\u001b[0m                                 Traceback (most recent call last)",
      "\u001b[0;32m~/miniconda3/envs/CLASSIFIER/lib/python3.6/site-packages/IPython/core/interactiveshell.py\u001b[0m in \u001b[0;36mrun_code\u001b[0;34m(self, code_obj, result, async_)\u001b[0m\n\u001b[1;32m   3334\u001b[0m             \u001b[0;32mif\u001b[0m \u001b[0mresult\u001b[0m \u001b[0;32mis\u001b[0m \u001b[0;32mnot\u001b[0m \u001b[0;32mNone\u001b[0m\u001b[0;34m:\u001b[0m\u001b[0;34m\u001b[0m\u001b[0;34m\u001b[0m\u001b[0m\n\u001b[1;32m   3335\u001b[0m                 \u001b[0mresult\u001b[0m\u001b[0;34m.\u001b[0m\u001b[0merror_in_exec\u001b[0m \u001b[0;34m=\u001b[0m \u001b[0msys\u001b[0m\u001b[0;34m.\u001b[0m\u001b[0mexc_info\u001b[0m\u001b[0;34m(\u001b[0m\u001b[0;34m)\u001b[0m\u001b[0;34m[\u001b[0m\u001b[0;36m1\u001b[0m\u001b[0;34m]\u001b[0m\u001b[0;34m\u001b[0m\u001b[0;34m\u001b[0m\u001b[0m\n\u001b[0;32m-> 3336\u001b[0;31m             \u001b[0mself\u001b[0m\u001b[0;34m.\u001b[0m\u001b[0mshowtraceback\u001b[0m\u001b[0;34m(\u001b[0m\u001b[0mrunning_compiled_code\u001b[0m\u001b[0;34m=\u001b[0m\u001b[0;32mTrue\u001b[0m\u001b[0;34m)\u001b[0m\u001b[0;34m\u001b[0m\u001b[0;34m\u001b[0m\u001b[0m\n\u001b[0m\u001b[1;32m   3337\u001b[0m         \u001b[0;32melse\u001b[0m\u001b[0;34m:\u001b[0m\u001b[0;34m\u001b[0m\u001b[0;34m\u001b[0m\u001b[0m\n\u001b[1;32m   3338\u001b[0m             \u001b[0moutflag\u001b[0m \u001b[0;34m=\u001b[0m \u001b[0;32mFalse\u001b[0m\u001b[0;34m\u001b[0m\u001b[0;34m\u001b[0m\u001b[0m\n",
      "\u001b[0;32m~/miniconda3/envs/CLASSIFIER/lib/python3.6/site-packages/IPython/core/interactiveshell.py\u001b[0m in \u001b[0;36mshowtraceback\u001b[0;34m(self, exc_tuple, filename, tb_offset, exception_only, running_compiled_code)\u001b[0m\n\u001b[1;32m   2035\u001b[0m                     \u001b[0;32mexcept\u001b[0m \u001b[0mException\u001b[0m\u001b[0;34m:\u001b[0m\u001b[0;34m\u001b[0m\u001b[0;34m\u001b[0m\u001b[0m\n\u001b[1;32m   2036\u001b[0m                         stb = self.InteractiveTB.structured_traceback(etype,\n\u001b[0;32m-> 2037\u001b[0;31m                                             value, tb, tb_offset=tb_offset)\n\u001b[0m\u001b[1;32m   2038\u001b[0m \u001b[0;34m\u001b[0m\u001b[0m\n\u001b[1;32m   2039\u001b[0m                     \u001b[0mself\u001b[0m\u001b[0;34m.\u001b[0m\u001b[0m_showtraceback\u001b[0m\u001b[0;34m(\u001b[0m\u001b[0metype\u001b[0m\u001b[0;34m,\u001b[0m \u001b[0mvalue\u001b[0m\u001b[0;34m,\u001b[0m \u001b[0mstb\u001b[0m\u001b[0;34m)\u001b[0m\u001b[0;34m\u001b[0m\u001b[0;34m\u001b[0m\u001b[0m\n",
      "\u001b[0;32m~/miniconda3/envs/CLASSIFIER/lib/python3.6/site-packages/IPython/core/ultratb.py\u001b[0m in \u001b[0;36mstructured_traceback\u001b[0;34m(self, etype, value, tb, tb_offset, number_of_lines_of_context)\u001b[0m\n\u001b[1;32m   1416\u001b[0m             \u001b[0mself\u001b[0m\u001b[0;34m.\u001b[0m\u001b[0mtb\u001b[0m \u001b[0;34m=\u001b[0m \u001b[0mtb\u001b[0m\u001b[0;34m\u001b[0m\u001b[0;34m\u001b[0m\u001b[0m\n\u001b[1;32m   1417\u001b[0m         return FormattedTB.structured_traceback(\n\u001b[0;32m-> 1418\u001b[0;31m             self, etype, value, tb, tb_offset, number_of_lines_of_context)\n\u001b[0m\u001b[1;32m   1419\u001b[0m \u001b[0;34m\u001b[0m\u001b[0m\n\u001b[1;32m   1420\u001b[0m \u001b[0;34m\u001b[0m\u001b[0m\n",
      "\u001b[0;32m~/miniconda3/envs/CLASSIFIER/lib/python3.6/site-packages/IPython/core/ultratb.py\u001b[0m in \u001b[0;36mstructured_traceback\u001b[0;34m(self, etype, value, tb, tb_offset, number_of_lines_of_context)\u001b[0m\n\u001b[1;32m   1316\u001b[0m             \u001b[0;31m# Verbose modes need a full traceback\u001b[0m\u001b[0;34m\u001b[0m\u001b[0;34m\u001b[0m\u001b[0;34m\u001b[0m\u001b[0m\n\u001b[1;32m   1317\u001b[0m             return VerboseTB.structured_traceback(\n\u001b[0;32m-> 1318\u001b[0;31m                 \u001b[0mself\u001b[0m\u001b[0;34m,\u001b[0m \u001b[0metype\u001b[0m\u001b[0;34m,\u001b[0m \u001b[0mvalue\u001b[0m\u001b[0;34m,\u001b[0m \u001b[0mtb\u001b[0m\u001b[0;34m,\u001b[0m \u001b[0mtb_offset\u001b[0m\u001b[0;34m,\u001b[0m \u001b[0mnumber_of_lines_of_context\u001b[0m\u001b[0;34m\u001b[0m\u001b[0;34m\u001b[0m\u001b[0m\n\u001b[0m\u001b[1;32m   1319\u001b[0m             )\n\u001b[1;32m   1320\u001b[0m         \u001b[0;32melif\u001b[0m \u001b[0mmode\u001b[0m \u001b[0;34m==\u001b[0m \u001b[0;34m'Minimal'\u001b[0m\u001b[0;34m:\u001b[0m\u001b[0;34m\u001b[0m\u001b[0;34m\u001b[0m\u001b[0m\n",
      "\u001b[0;32m~/miniconda3/envs/CLASSIFIER/lib/python3.6/site-packages/IPython/core/ultratb.py\u001b[0m in \u001b[0;36mstructured_traceback\u001b[0;34m(self, etype, evalue, etb, tb_offset, number_of_lines_of_context)\u001b[0m\n\u001b[1;32m   1184\u001b[0m         \u001b[0mexception\u001b[0m \u001b[0;34m=\u001b[0m \u001b[0mself\u001b[0m\u001b[0;34m.\u001b[0m\u001b[0mget_parts_of_chained_exception\u001b[0m\u001b[0;34m(\u001b[0m\u001b[0mevalue\u001b[0m\u001b[0;34m)\u001b[0m\u001b[0;34m\u001b[0m\u001b[0;34m\u001b[0m\u001b[0m\n\u001b[1;32m   1185\u001b[0m         \u001b[0;32mif\u001b[0m \u001b[0mexception\u001b[0m\u001b[0;34m:\u001b[0m\u001b[0;34m\u001b[0m\u001b[0;34m\u001b[0m\u001b[0m\n\u001b[0;32m-> 1186\u001b[0;31m             \u001b[0mformatted_exceptions\u001b[0m \u001b[0;34m+=\u001b[0m \u001b[0mself\u001b[0m\u001b[0;34m.\u001b[0m\u001b[0mprepare_chained_exception_message\u001b[0m\u001b[0;34m(\u001b[0m\u001b[0mevalue\u001b[0m\u001b[0;34m.\u001b[0m\u001b[0m__cause__\u001b[0m\u001b[0;34m)\u001b[0m\u001b[0;34m\u001b[0m\u001b[0;34m\u001b[0m\u001b[0m\n\u001b[0m\u001b[1;32m   1187\u001b[0m             \u001b[0metype\u001b[0m\u001b[0;34m,\u001b[0m \u001b[0mevalue\u001b[0m\u001b[0;34m,\u001b[0m \u001b[0metb\u001b[0m \u001b[0;34m=\u001b[0m \u001b[0mexception\u001b[0m\u001b[0;34m\u001b[0m\u001b[0;34m\u001b[0m\u001b[0m\n\u001b[1;32m   1188\u001b[0m         \u001b[0;32melse\u001b[0m\u001b[0;34m:\u001b[0m\u001b[0;34m\u001b[0m\u001b[0;34m\u001b[0m\u001b[0m\n",
      "\u001b[0;31mTypeError\u001b[0m: must be str, not list"
     ]
    }
   ],
   "source": [
    "# You may need to restart your runtime prior to this, to let your installation take effect\n",
    "# Some basic setup:\n",
    "# Setup detectron2 logger\n",
    "import detectron2\n",
    "from detectron2.utils.logger import setup_logger\n",
    "setup_logger()\n",
    "\n",
    "# import some common libraries\n",
    "import numpy as np\n",
    "import cv2\n",
    "import random\n",
    "\n",
    "# import some common detectron2 utilities\n",
    "from detectron2 import model_zoo\n",
    "from detectron2.engine import DefaultPredictor\n",
    "from detectron2.config import get_cfg\n",
    "from detectron2.utils.visualizer import Visualizer\n",
    "from detectron2.data import MetadataCatalog"
   ]
  },
  {
   "cell_type": "code",
   "execution_count": null,
   "metadata": {},
   "outputs": [],
   "source": []
  }
 ],
 "metadata": {
  "kernelspec": {
   "display_name": "Python 3",
   "language": "python",
   "name": "python3"
  },
  "language_info": {
   "codemirror_mode": {
    "name": "ipython",
    "version": 3
   },
   "file_extension": ".py",
   "mimetype": "text/x-python",
   "name": "python",
   "nbconvert_exporter": "python",
   "pygments_lexer": "ipython3",
   "version": "3.6.10"
  }
 },
 "nbformat": 4,
 "nbformat_minor": 2
}
